Workbook

Sheet Dashboard
A1: HEALTH, SAFETY & ENVIRONMENT — SCORE CARD DASHBOARD
A2: Period: 1st & 2nd Week, September 2026
A3: No | B3: Section | C3: Responsible | D3: Allocated Score | E3: Actual Score | F3: Adjustable Score | G3: Actual Score | H3: Adjustable Score
A4: 1 | B4: General Maintenance | C4: Ruwandika | D4: ='General Maintenance'!E40 -> 465 | E4: ='General Maintenance'!F40 -> 265 | F4: ='General Maintenance'!G40 -> 330 | G4: 57 | H4: 71
A5: 2 | B5: Admin | C5: Dalton | D5: =Admin!E29 -> 265 | E5: =Admin!F29 -> 225 | F5: =Admin!G29 -> 245 | G5: 85 | H5: 92
A6: 3 | B6: RM Stores | C6: Chandrasiri | D6: ='RM Stores'!E35 -> 235 | E6: ='RM Stores'!F35 -> 205 | F6: ='RM Stores'!G35 -> 215 | G6: 87 | H6: 91
A7: 4 | B7: FG | C7: Chandrasiri | D7: =FG!E28 -> 155 | E7: =FG!F28 -> 130 | F7: =FG!G28 -> 130 | G7: 84 | H7: 84
A8: 5 | B8: Accessories | C8: Sampath | D8: =Accessories!E36 -> 225 | E8: =Accessories!F36 -> 160 | F8: =Accessories!G36 -> 180 | G8: 71 | H8: 80
A9: 6 | B9: Cutting | C9: Chamila | D9: =Cutting!E29 -> 155 | E9: =Cutting!F29 -> 155 | F9: =Cutting!G29 -> 155 | G9: 100 | H9: 100
A10: 7 | B10: Ground floor modules & Molding | C10: Gamini | D10: ='Ground floor modules & Molding'!E38 -> 265 | E10: ='Ground floor modules & Molding'!F38 -> 205 | F10: ='Ground floor modules & Molding'!G38 -> 225 | G10: 77 | H10: 85
A11: 8 | B11: Packing | C11: Gamini | D11: ='Packing '!E26 -> 140 | E11: ='Packing '!F26 -> 140 | F11: ='Packing '!G26 -> 140 | G11: 100 | H11: 100
A12: 9 | B12: Audit room & Final Inspection | C12: Lalinda | D12: ='Audit room & Final Inspection'!E25 -> 95 | E12: ='Audit room & Final Inspection'!F25 -> 80 | F12: ='Audit room & Final Inspection'!G25 -> 95 | G12: 84 | H12: 100
A13: 10 | B13: Lab & CPI | C13: Chandani | D13: ='Lab & CPI'!E26 -> 130 | E13: ='Lab & CPI'!F26 -> 115 | F13: ='Lab & CPI'!G26 -> 130 | G13: 88 | H13: 100
A14: 11 | B14: Screen Printing & Modules | C14: Gamini | D14: ='Screen Printing & Modules'!E35 -> 210 | E14: ='Screen Printing & Modules'!F35 -> 125 | F14: ='Screen Printing & Modules'!G35 -> 140 | G14: 60 | H14: 67
A15: 12 | B15: Sample Room | C15: Samitha | D15: ='Sample Room'!D32 -> 180 | E15: ='Sample Room'!E32 -> 170 | F15: ='Sample Room'!F32 -> 180 | G15: 94 | H15: 100
A16: 13 | B16: Coating | C16: Chandani | D16: =Coating!D35 -> 205 | E16: =Coating!E35 -> 190 | F16: =Coating!F35 -> 190 | G16: 93 | H16: 93
A17: 14 | B17: Forte | C17: Cooray | D17: ='Forte '!E27 -> 180 | E17: ='Forte '!F27 -> 180 | F17: ='Forte '!G27 -> 180 | G17: 100 | H17: 100
A18: 15 | B18: IE | C18: Dilan | D18: =IE!D30 -> 220 | E18: =IE!E30 -> 130 | F18: =IE!F30 -> 150 | G18: 59 | H18: 68
A19: 16 | B19: Training School | C19: Dilan | D19: ='Training School'!E30 -> 130 | E19: ='Training School'!F30 -> 130 | F19: ='Training School'!G30 -> 130 | G19: 100 | H19: 100
A20: 17 | B20: Medical Centre | C20: Nadee | D20: ='Medical Centre'!E21 -> 100 | E20: ='Medical Centre'!F21 -> 95 | F20: ='Medical Centre'!G21 -> 95 | G20: 95 | H20: 95
A21: TOTAL | G21: =SUM(G4:G20) -> 1434 | H21: =SUM(H4:H20) -> 1526
A22: HCE Score % | G22: =G21/17 -> 84.352941

Sheet Rating System
A1: HEALTH, SAFETY & ENVIRONMENT SCORING SYSTEM
C2: CAT 06 (20 marks) | D2: CAT 05 (15 marks) | E2: CAT 04 (10 marks) | F2: CAT 03 (05 marks)
A3: 1 | B3: Failing from height | C3: Material falling from a height & falling from height and caused severe injury
A4: 2 | B4: Structural Safety | C4: Structurally unsafe constructions & severe cracks not investigated
D5: Floor or roof openings which are not guarded.
A6: 3 | B6: Sanitation facilities | C6: Unreasonable restrictions to toilets & drinking water
D7: Clean and consumable drinking water not available and not identified
D8: No doors on toilets to give privacy
D9: Extremely poor hygiene, posing a risk to health.
E10: No flushing or washing water/soap
E11: Insufficient number of toilets in ratio
E12: Inadequate level of cleanliness in washrooms
F13: No hand drying facilities.
A14: 4 | B14: Food Safety | D14: Extremely poor hygiene in food storage / service / preparation areas, posing a risk to health. | F14: Inadequate hygiene in food storage and preparation areas.
E15: Appropriate health and safety certifications and qualifications for food handlers
E16: Poor hygiene of food handlers.
A17: 5 | B17: Work Environment | E17: No protection from extreme temperatures | F17: Protection from extreme temperatures is inadequate.
E18: Severe lack of ventilation or adequate lighting | F18: Inadequate lighting and/or ventilation.
A19: 6 | B19: Waste Disposal | D19: Severe AND/OR deliberate environmental pollution including; direct discharge of contaminated industrial wastewater into inland water receiver
D20: Hazardous wastes inadequately labelled or disposed of.
D21: No waste disposal records
D22: Hazardous wastes not stored in designated or secure areas.
D23: Waste water discharge and emissions not monitored in line with regulatory requirements.
D24: No maintenance programmes or operating procedures developed or implemented for in-house waste water treatment facilities.
D25: Chemical and drum storage areas not covered to prevent rainwater from coming into contact with chemicals and drums
D26: Insufficient/poorly maintained storage facilities for chemicals, oil, diesel, etc. which lead to contamination of land. | E26: Insufficient/poorly maintained storage facilities for chemicals, oil, diesel etc. (secondary containment must be 110% of volume of primary container)
E27: Bins should be provided for the disposal of sanitary and medical waste.
E28: Hazardous waste containers in poor condition.
E29: Hazardous waste not stored properly in a dedicated area for disposal.
A30: 7 | B30: Fire Safety | C30: No Fire fighting equipment on site.
C31: No fire alarm system
C32: Locked fire exits.
C33: No emergency lighting | E33: Emergency lighting inadequate
C34: Fire alarm cannot be heard in all areas.
D35: Flammable materials and combustible solid/liquid materials stored in stairwells/under stairs/doorways.
D36: Insufficient number of exits.
E37: Access to fire detection system/ fire protection equipment/fire alarms is blocked.
E38: Fire protection equipment is not maintained | F38: Fire exits not adequately signed.
E39: Blocked aisles or exits, obstructing exit/s. | F39: Inadequate number of fire extinguishers
E40: Exit doors are not designed to open outwards. | F40: No visual inspection or maintenance records of fire equipment including: Fire alarm/ fire equipment including:Extinguishers / hoses / hydrants / sprinklers/ Emergency lighting/ Smoke / heat detectors
...

Sheet General Maintenance
L2: General Maintenance
B3: Engineering (Factory premises/canteen/panel room/Generator room/Compressor room/construction area/STP/All areas) | J3: Engineering (Factory premises/canteen/panel room/Generator room/Compressor room/construction area/STP/All areas)
C4: Description | D4: Responsibility | E4: Allocated Score | F4: Accurate Score | G4: Adjustable score | H4: Remark | K4: Description
C5: Emergency Response | K5: Emergency Response | L5: Factory Engineer | M5: Factory Manager | N5: Executive Compliance | O5: Assistant Compliance | Q5: R | R5: Responsible
B6: Canteen | C6: Table,chairs, Tap and electric equipment, fences not broken ( Boiler, Fan, Light, Emergency light) | D6: General Maintenance | E6: 20 | F6: 0 | G6: 20 | H6: Catering Table broken, Cupboard doors broken, Some fans are not properly working | J6: Canteen | K6: Table,chairs, Tap and electric equipment, fences not broken ( Boiler, Fan, Light, Emergency light) | L6: R | M6: A | N6: C | O6: I | Q6: A | R6: Accountable
B7: Washrooms | C7: Squatting pans, commodes, wash basins, tilesand doors are in with good condition with no damages | D7: General Maintenance | E7: 20 | F7: 20 | G7: 20 | J7: Washrooms | K7: Squatting pans, commodes, wash basins, tilesand doors are in with good condition with no damages | L7: R | M7: A | N7: C | O7: I | Q7: C | R7: Consulted
C8: Insufficient number of toilets in ratio | D8: General Maintenance | E8: 10 | F8: 10 | G8: 10 | K8: Insufficient number of toilets in ratio | L8: R | M8: A | N8: C | O8: I | Q8: I | R8: Informed
B9: Pump Room | C9: Condition monitoring system available for fire pump system including water sump and working in good condition | D9: General Maintenance | E9: 5 | F9: 5 | G9: 5 | J9: Pump Room | K9: Condition monitoring system available for fire pump system including water sump and working in good condition | L9: R | M9: A | N9: C | O9: I
B10: Construction area | C10: Contractors use suitable PPE s depending on the nature of work | D10: General Maintenance | E10: 15 | F10: 15 | G10: 15 | J10: Construction area | K10: Contractors use suitable PPE s depending on the nature of work | L10: R | M10: A | N10: C | O10: I
C11: Work permits are available where outside contractors doing following works - Hot works/ work at height/ excavations | D11: General Maintenance | E11: 10 | F11: 10 | G11: 10 | K11: Work permits are available where outside contractors doing following works - Hot works/ work at height/ excavations | L11: R | M11: A | N11: C | O11: I
B12: Factory Premises | C12: The Perimeter wall/fence is in good condition around the facility | D12: General Maintenance | E12: 20 | F12: 20 | G12: 20 | J12: Factory Premises | K12: The Perimeter wall/fence is in good condition around the facility | L12: R | M12: A | N12: C | O12: I
C13: Portable Drinking water sources are identified and labeled. | D13: General Maintenance | E13: 15 | F13: 15 | G13: 15 | K13: Portable Drinking water sources are identified and labeled. | L13: R | M13: A | N13: C | O13: I
C14: Confined spaces are locked and authorized access only | D14: General Maintenance | E14: 5 | F14: 0 | G14: 0 | H14: STP Area | K14: Confined spaces are locked and authorized access only | L14: R | M14: A | N14: C | O14: I
C15: Tiles or floor damages | D15: General Maintenance | E15: 20 | F15: 0 | G15: 0 | H15: Loading Bay area/ Upper floor | K15: Tiles or floor damages | L15: R | M15: A | N15: C | O15: I
C16: Exist should be Easy to access | D16: General Maintenance | E16: 20 | F16: 20 | G16: 20
C17: Access Control area's Lockable | D17: General Maintenance | E17: 10 | F17: 10 | G17: 10 | K17: Access Control area's Lockable | L17: R | M17: A | N17: C | O17: I
B18: Emergency Response (All Areas) | C18: Emergency lights available & working and sufficient lighting is available | D18: General Maintenance | E18: 20 | F18: 0 | G18: 20 | H18: Emergency lights are insufficient in the main aisle of the upper production area | J18: Emergency Response (Guard room/ Canteen/ Waste Yard) | K18: Emergency lights available & working and sufficient lighting is available | L18: R | M18: A | N18: C | O18: I
C19: Fire alarm system and hose reals are accessible ,available & active throughout the area | D19: General Maintenance | E19: 20 | F19: 0 | G19: 0 | H19: Fire panel board display issue | K19: Fire alarm system and hose reals are accessible ,available & active throughout the area | L19: R | M19: A | N19: C | O19: I
C20: A minimum of 2 exits for each room where more than 05 occupants working | D20: General Maintenance | E20: 15 | F20: 0 | G20: 0 | H20: HR | K20: A minimum of 2 exits for each room where more than 05 occupants working | L20: R | M20: A | N20: C | O20: I
C21: Exist should be outwards at each room & floor & fixed with self-closing devices | D21: General Maintenance | E21: 5 | F21: 0 | G21: 0 | H21: Audit rooms and production office | K21: Exist should be outwards at each room & floor & fixed with self-closing devices | L21: R | M21: A | N21: C | O21: I
C22: Manual call points are installed on all escape routes, particularly at all stairway entrances and exits to open air | D22: General Maintenance | E22: 20 | F22: 20 | G22: 20 | K22: Manual call points Installed on all escape routes and in particular all stairwell entrances and all exits to open air. | L22: R | M22: A | N22: C | O22: I
C23: Smoke detectors/beam detectors/Fire call points & Fire fighting equipment not obstructed | D23: General Maintenance | E23: 10 | F23: 0 | G23: 0 | H23: smoke generate in Piping Area, therefore that area 2 smoke detectors were closed by employees | K23: Smoke detectors/beam detectors/Fire call points & Fire fighting equipment not obstructed | L23: R | M23: A | N23: C | O23: I
C24: Fire safety sign boards are displayed in each area (fire alarm call points/ fire extinguishers/ Fire siren/ fire hose reel) | D24: General Maintenance | E24: 5 | F24: 0 | G24: 5 | H24: Canteen area sign board is not arrange properly | K24: Fire safety sign boards are displayed in each area (fire alarm call points/ fire extinguishers/ Fire siren/ fire hose reel) | L24: R | M24: A | N24: C | O24: I
C25: Emergency exits pathways are not obstructed | D25: General Maintenance | E25: 10 | F25: 0 | G25: 0 | H25: Upper Floor Production area emergency pathways blocked by AC unit, | K25: Emergency exits pathways are not obstructed | L25: R | M25: A | N25: C | O25: I
C26: Width of each pathway or gangway is greater than 2.5ft (30 inches) | D26: General Maintenance | E26: 10 | F26: 0 | G26: 0 | H26: Production area pathways, Macpi area | K26: Width of each pathway or gangway is greater than 2.5ft (30 inches) | L26: R | M26: A | N26: C | O26: I
C27: Fire attendance registers are marked daily | D27: General Maintenance | E27: 10 | F27: 10 | G27: 10 | K27: Fire attendance registers are marked daily | L27: R | M27: A | N27: C | O27: I
B28: Electrical Safety (all areas) | C28: Electrical equipment (i.e. electrical panels, fuse/breaker boxes) are accessible and free of obstructions | D28: General Maintenance | E28: 10 | F28: 10 | G28: 10 | J28: Electrical Safety (all areas) | K28: Electrical equipment (i.e. electrical panels, fuse/breaker boxes) are accessible and free of obstructions | L28: R | M28: A | N28: C | O28: I
C29: Rubber Carpets are provided beneath the Electrical Panels | D29: General Maintenance | E29: 5 | F29: 5 | G29: 5 | K29: Rubber Carpets are provided beneath the Electrical Panels | L29: R | M29: A | N29: C | O29: I
C30: Electrical enclosures (i.e. switches, receptacles, junction boxes, etc.) are provided with tight fitting covers or plates and updated check list | D30: General Maintenance | E30: 15 | F30: 15 | G30: 15 | K30: Electrical enclosures (i.e. switches, receptacles, junction boxes, etc.) are provided with tight fitting covers or plates and updated check list | L30: R | M30: A | N30: C | O30: I
C31: Flexible cords and cables free of frayed wiring or deteriorated insulation and not going through the pathways | D31: General Maintenance | E31: 20 | F31: 0 | G31: 0 | H31: Energy pools are not providing some areas, Exposed wires on pathways, CPI area | K31: Flexible cords and cables free of frayed wiring or deteriorated insulation and not going through the pathways | L31: R | M31: A | N31: C | O31: I
B32: Machine Safety | C32: Moving parts of exhaust fans, blowers etc. have been covered adequately | D32: General Maintenance | E32: 20 | F32: 0 | G32: 0 | H32: Veit room | J32: Machine Safety | K32: Moving parts of exhaust fans, blowers etc. have been covered adequately | L32: R | M32: A | N32: C | O32: I
B33: PPEs | C33: PPEs are used by all employees when they are necessary | D33: General Maintenance | E33: 15 | F33: 15 | G33: 15 | J33: PPEs | K33: PPEs are used by all employees when they are necessary | L33: R | M33: A | N33: C | O33: I
B34: Chemical safety | C34: Chemical containers are in good condition and stored in separate containers and incompatible chemicals stored separately | D34: General Maintenance | E34: 20 | F34: 20 | G34: 20 | J34: Chemical safety | K34: Chemical containers are in good condition and stored in separate containers and incompatible chemicals stored separately | L34: R | M34: A | N34: C | O34: I
C35: PPEs and Spill kits available near chemical storing and using areas | D35: General Maintenance | E35: 15 | F35: 15 | G35: 15 | K35: PPEs and Spill kits available near chemical storing and using areas | L35: R | M35: A | N35: C | O35: I
C36: Eye wash station / shower available & working in good condition, Fresh & isolated water supply is available for eye wash stations with adequate flow rate & pressure | D36: General Maintenance | E36: 10 | F36: 10 | G36: 10 | K36: Eye wash station / shower available & working in good condition, Fresh & isolated water supply is available for eye wash stations with adequate flow rate & pressure | L36: R | M36: A | N36: C | O36: I
B37: Others | C37: Air receivers, pressure vessels, chillers etc. are mounted properly | D37: General Maintenance | E37: 5 | F37: 5 | G37: 5 | J37: Others | K37: Air receivers, pressure vessels, chillers etc. are mounted properly | L37: R | M37: A | N37: C | O37: I
C38: Facility Maintenance | D38: General Maintenance | E38: 20 | F38: 0 | G38: 20 | H38: 500kg Material hoist door not properly closed ,Glare Issue in Cutting Area from Windows
C39: Stairs are clear of obstructions and not stored items under exit stairs | D39: General Maintenance | E39: 15 | F39: 15 | G39: 15 | K39: Stairs are clear of obstructions and not stored items under exit stairs | L39: R | M39: A | N39: C | O39: I
C40: Total | E40: =SUM(E5:E39) -> 465 | F40: =SUM(F5:F39) -> 265 | G40: =SUM(G5:G39) -> 330
C41: % | E41: =(E40/E40)*100 -> 100 | F41: =+F40/E40*100 -> 56.989247 | G41: =+G40/E40*100 -> 70.967742
...

Sheet Admin
J2: Admin
B3: Admin (Factory premises/ Guard room/canteen/waste yard/panel room/Generator room/Compressor room/construction area/STP/All areas) | J3: Admin (Factory premises/ Guard room/canteen/waste yard/panel room/Generator room/Compressor room/construction area/STP/All areas)
C4: Description | D4: Responsibility | E4: Allocated Score | F4: Accurate Score | G4: Adjustable score | H4: Remark | K4: Description
C5: Emergency Response | K5: Emergency Response | L5: Admin Senior Executive | M5: Assistant Admin (Waste) | N5: Assistant Admin (Guard Room) | O5: Executive Compliance | P5: Assistant Compliance | R5: R | S5: Responsible
B6: Canteen | C6: Separate waste collection bins are provided for collection of waste materials (Foot operated or closed lid) | D6: Admin | E6: 10 | F6: 10 | G6: 10 | J6: Canteen | K6: Separate waste collection bins are provided for collection of waste materials (Foot operated or closed lid) | L6: A | M6: R | N6: R | O6: C | P6: I | R6: A | S6: Accountable
C7: All food handling and processing areas are free of pests/animals and maintaining proper hygiene | D7: Admin | E7: 5 | F7: 5 | G7: 5 | K7: All food handling and processing areas are free of pests/animals and maintaining proper hygiene | L7: A | M7: R | N7: R | O7: C | P7: I | R7: C | S7: Consulted
C8: Every person engaged in food handling are maintained a high degree of personal cleanliness, and wear suitable protective clothing including head covering, gloves, masks and foot wear. | D8: Admin | E8: 10 | F8: 10 | G8: 10 | K8: Every person engaged in food handling are maintained a high degree of personal cleanliness, and wear suitable protective clothing including head covering, gloves, masks and foot wear. | L8: A | M8: R | N8: R | O8: C | P8: I | R8: I | S8: Informed
C9: Kitchen is designed to prevent cross-contamination (effective means between different operations) | D9: Admin | E9: 15 | F9: 0 | G9: 0 | H9: Corrective action is not taken as a PHI record direction | K9: Kitchen is designed to prevent cross-contamination (effective means between different operations) | L9: A | M9: R | N9: R | O9: C | P9: I
B10: Washrooms | C10: Covered bins available in toilets | D10: Admin | E10: 10 | F10: 10 | G10: 10 | J10: Washrooms | K10: Covered bins available in toilets | L10: A | M10: R | N10: R | O10: C | P10: I
C11: Soaps/ Hand washes are available | D11: Admin | E11: 10 | F11: 0 | G11: 10 | H11: One hand dispenser in the canteen area is broken | K11: Soaps/ Hand washes are available | L11: A | M11: R | N11: R | O11: C | P11: I
C12: Hand drying facilities. | D12: Admin | E12: 5 | F12: 0 | G12: 0 | H12: Not providing workers wash rooms | K12: hand drying facilities. | L12: A | M12: R | N12: R | O12: C | P12: I
C13: Toilets are clean, cleaning charts are available | D13: Admin | E13: 10 | F13: 10 | G13: 10 | K13: Toilets are clean, cleaning charts are available | L13: A | M13: R | N13: R | O13: C | P13: I
B14: Guard room | C14: Contractor Entry register is maintained at the guard room as per the annexure on Contractor ESH Guidelines | D14: Admin | E14: 5 | F14: 5 | G14: 5 | J14: Guard room | K14: Contractor Entry register is maintained at the guard room as per the annexure on Contractor ESH Guidelines | L14: A | M14: R | N14: R | O14: C | P14: I
C15: Contractors use equipment & tools with safe condition | D15: Admin | E15: 15 | F15: 15 | G15: 15 | K15: Contractors use equipment & tools with safe condition | L15: A | M15: R | N15: R | O15: C | P15: I
C16: Exist should be not closed and should be clean | D16: Admin | E16: 20 | F16: 20 | G16: 20 | K16: Exist should be not closed | L16: A | M16: R | N16: R | O16: C | P16: I
B17: Waste Yard | C17: Hazardous and non-hazardous waste are stored with proper segregation | D17: Admin | E17: 10 | F17: 0 | G17: 10 | H17: Waste yard filled cannot find proper segregation | J17: Waste Yard | K17: Hazardous and non-hazardous waste are stored with proper segregation | L17: A | M17: R | N17: R | O17: C | P17: I
C18: No water collecting areas to prevent mosquito breeding | D18: Admin | E18: 5 | F18: 5 | G18: 5 | K18: No water collecting areas to prevent mosquito breeding | L18: A | M18: R | N18: R | O18: C | P18: I
B19: Factory Premises | C19: Emergency Pathways should not be obstruct | D19: Admin | E19: 20 | F19: 20 | G19: 20 | J19: Factory Premises | K19: Emergency Pathways should not be obstruct | L19: A | M19: R | N19: R | O19: C | P19: I
C20: Emergency Exist doors are not closed | D20: Admin | E20: 20 | F20: 20 | G20: 20 | K20: Emergency Exist doors are not closed | L20: A | M20: R | N20: R | O20: C | P20: I
B21: Powered motor vehicles (PMV) | C21: Emergency contact numbers displayed in transportation vehicles | D21: Admin | E21: 5 | F21: 5 | G21: 5 | J21: Powered motor vehicles (PMV) | K21: Emergency contact numbers displayed in transportation vehicles | L21: A | M21: R | N21: R | O21: C | P21: I
B22: PPEs | C22: PPEs are used by all employees when they are necessary | D22: Admin | E22: 15 | F22: 15 | G22: 15 | J22: PPEs | K22: PPEs are used by all employees when they are necessary | L22: A | M22: R | N22: R | O22: C | P22: I
B23: Chemical Safety | C23: Chemical containers are in good condition and stored in separate containers and incompatible chemicals stored separately | D23: Admin | E23: 20 | F23: 20 | G23: 20 | J23: Chemical Safety | K23: Chemical containers are in good condition and stored in separate containers and incompatible chemicals stored separately | L23: A | M23: R | N23: R | O23: C | P23: I
C24: PPEs and Spill kits available near chemical storing and using areas | D24: Admin | E24: 15 | F24: 15 | G24: 15 | K24: PPEs and Spill kits available near chemical storing and using areas | L24: A | M24: R | N24: R | O24: C | P24: I
C25: Eye wash station / showers are proper cleaning | D25: Admin | E25: 10 | F25: 10 | G25: 10 | K25: Eye wash station / shower available & working in good condition, Fresh & isolated water supply is available for eye wash stations with adequate flow rate & pressure | L25: A | M25: R | N25: R | O25: C | P25: I
B26: Emergency Response (Guard room/ Canteen/ Waste Yard) | C26: Smoke detectors/beam detectors/Fire call points & Fire fighting equipment not obstructed | D26: Admin | E26: 10 | F26: 10 | G26: 10 | J26: Emergency Response (Guard room/ Canteen/ Waste Yard) | K26: Smoke detectors/beam detectors/Fire call points & Fire fighting equipment not obstructed | L26: A | M26: R | N26: R | O26: C | P26: I
B27: Other | C27: Stairs are clear of obstructions and not stored items under exit stairs | D27: Admin | E27: 15 | F27: 15 | G27: 15 | J27: Other | K27: Stairs are clear of obstructions and not stored items under exit stairs | L27: A | M27: R | N27: R | O27: C | P27: I
C28: Proper housekeeping are maintained | D28: Admin | E28: 5 | F28: 5 | G28: 5
C29: Total | E29: =SUM(E2:E28) -> 265 | F29: =SUM(F2:F28) -> 225 | G29: =SUM(G2:G28) -> 245
C30: % | E30: =+(E29/E29)*100 -> 100 | F30: =+F29/E29*100 -> 84.90566 | G30: =+G29/E29*100 -> 92.45283
Q38: Electrical panel checklist

Sheet RM Stores
B4: Stores (Loading bay/RM Stores/ Chemical room) | J4: Stores (Loading bay/RM Stores/FG/ Chemical room)
B5: Description | D5: Responsibility | E5: Allocated Score | F5: Accurate Score | G5: Adjustable score | H5: Remark | J5: Description
B6: Emergency response | J6: Emergency response | L6: Executive Stores | M6: Senior Executive Stores | N6: Executive Compliance | O6: Assistant Compliance
B7: 1 | C7: Emergency Exist doors are not closed | D7: Stores | E7: 20 | F7: 20 | G7: 20 | J7: 1 | K7: Emergency Exist doors are not closed | L7: R | M7: A | N7: C | O7: I | Q7: R | R7: Responsible
B8: 2 | C8: Emergency exits pathways are not obstructed | D8: Stores | E8: 10 | F8: 0 | G8: 10 | H8: In adhisive room | J8: 2 | K8: Emergency exits pathways are not obstructed | L8: R | M8: A | N8: C | O8: I | Q8: A | R8: Accountable
B9: 3 | C9: Smoke detectors/beam detectors/Fire call points & Fire fighting equipment are not obstructed | D9: Stores | E9: 10 | F9: 10 | G9: 10 | J9: 3 | K9: Smoke detectors/beam detectors/Fire call points & Fire fighting equipment are not obstructed | L9: R | M9: A | N9: C | O9: I | Q9: C | R9: Consulted
B10: 4 | C10: Fire attendance registers are marked daily in all Departments | D10: Stores | E10: 10 | F10: 10 | G10: 10 | J10: 4 | K10: Fire attendance registers are marked daily in all Departments | L10: R | M10: A | N10: C | O10: I | Q10: I | R10: Informed
B11: First Aid | J11: First Aid
B12: 5 | C12: First aid box is not obstructed | D12: Stores | E12: 10 | F12: 10 | G12: 10 | J12: 5 | K12: First aid box is not obstructed | L12: R | M12: A | N12: C | O12: I
B13: Electrical Safety | J13: Electrical Safety
B14: 6 | C14: Electrical equipment (i.e. electrical panels, fuse/breaker boxes) are accessible and free of obstructions | D14: Stores | E14: 10 | F14: 10 | G14: 10 | J14: 6 | K14: Electrical equipment (i.e. electrical panels, fuse/breaker boxes) are accessible and free of obstructions | L14: R | M14: A | N14: C | O14: I
B15: Machine Safety | J15: Machine Safety
B16: 7 | C16: Material hoist handling safely. | D16: Stores | E16: 15 | F16: 0 | G16: 0 | H16: Material hoist door is not properly closed during the process | J16: 7 | K16: Material hoist handling safely. | L16: R | M16: A | N16: C | O16: I
B17: Personal Protective Equipment (PPEs) | J17: Personal Protective Equipment (PPEs)
B18: 8 | C18: PPEs are used by all employees when they are necessary | D18: Stores | E18: 15 | F18: 15 | G18: 15 | J18: 8 | K18: PPEs are used by all employees when they are necessary | L18: R | M18: A | N18: C | O18: I
B19: Chemical Safety | J19: Chemical Safety
B20: 9 | C20: Chemical containers are in good condition and stored in separate containers and incompatible chemicals stored separately | D20: Stores | E20: 20 | F20: 20 | G20: 20 | J20: 9 | K20: Chemical containers are in good condition and stored in separate containers and incompatible chemicals stored separately | L20: R | M20: A | N20: C | O20: I
B21: 10 | C21: Chemical cans and secondary containers are named & labels are included name, purchased date, expiry date, GHS sign | D21: Stores | E21: 15 | F21: 15 | G21: 15 | J21: 10 | K21: Chemical cans and secondary containers are named & labels are included name, purchased date, expiry date, GHS sign | L21: R | M21: A | N21: C | O21: I
B22: 11 | C22: Current Stock details of Chemicals maintained & all chemicals are included in the chemical inventory | D22: Stores | E22: 5 | F22: 0 | G22: 0 | H22: Chemical Stock and system detailed mismatched | J22: 11 | K22: Current Stock details of Chemicals maintained & all chemicals are included in the chemical inventory | L22: R | M22: A | N22: C | O22: I
B23: 12 | C23: Spill kits are available in the chemical using areas | D23: Stores | E23: 10 | F23: 10 | G23: 10 | J23: 12 | K23: Spill kits are available in the chemical using areas | L23: R | M23: A | N23: C | O23: I
B24: 13 | C24: Flammable chemicals are stored separately | D24: Stores | E24: 15 | F24: 15 | G24: 15 | J24: 13 | K24: Flammable chemicals are stored separately | L24: R | M24: A | N24: C | O24: I
B25: Sharp Tool Safety | J25: Sharp Tool Safety
B26: 14 | C26: Sharp tools are hung & tied properly | D26: Stores | E26: 5 | F26: 5 | G26: 5 | J26: 14 | K26: Sharp tools are hung & tied properly | L26: R | M26: A | N26: C | O26: I
B27: 15 | C27: Tool inventory is maintained properly | D27: Stores | E27: 5 | F27: 5 | G27: 5 | J27: 15 | K27: Tool inventory is maintained properly | L27: R | M27: A | N27: C | O27: I
B28: 16 | C28: Not Handling loose blades | D28: Stores | E28: 5 | F28: 5 | G28: 5 | J28: 16 | K28: Not Handling loose blades | L28: R | M28: A | N28: C | O28: I
B29: Other | J29: Other
B30: 17 | C30: Stairs are clear of obstructions and not stored items under exit stairs | D30: Stores | E30: 15 | F30: 15 | G30: 15 | J30: 17 | K30: Stairs are clear of obstructions and not stored items under exit stairs | L30: R | M30: A | N30: C | O30: I
B31: 18 | C31: Cartons are stacked at safe height (6ft) (Material falling from a height) | D31: Stores | E31: 20 | F31: 20 | G31: 20 | J31: 18 | K31: Cartons are stacked at safe height (6ft) (Material falling from a height) | L31: R | M31: A | N31: C | O31: I
B32: 19 | C32: Safety Ladders are used | D32: Stores | E32: 10 | F32: 10 | G32: 10 | J32: 19 | K32: Safety Ladders are used | L32: R | M32: A | N32: C | O32: I
B33: 20 | C33: Loading and unloading area is closed with chain when there is no loading/unloading | D33: Stores | E33: 5 | F33: 5 | G33: 5 | J33: 20 | K33: Loading and unloading area is closed with chain when there is no loading/unloading | L33: R | M33: A | N33: C | O33: I
B34: 21 | C34: Proper housekeeping are maintained | D34: Stores | E34: 5 | F34: 5 | G34: 5 | J34: 21 | K34: Proper housekeeping are maintained | L34: R | M34: A | N34: C | O34: I
C35: Total | E35: =SUM(E7:E34) -> 235 | F35: =SUM(F5:F34) -> 205 | G35: =SUM(G5:G34) -> 215
C36: % | E36: =(E35/E35)*100 -> 100 | F36: =+F35/E35*100 -> 87.234043 | G36: =+G35/E35*100 -> 91.489362

Sheet FG
B4: Stores (FG) | J4: Stores (Loading bay/RM Stores/FG/ Chemical room)
B5: Description | D5: Responsibility | E5: Allocated Score | F5: Accurate Score | G5: Adjustable score | H5: Remark | J5: Description
B6: Emergency response | J6: Emergency response | L6: Executive Stores | M6: Senior Executive Stores | N6: Executive Compliance | O6: Assistant Compliance
B7: 1 | C7: Emergency Exist doors are not closed | D7: Stores | E7: 20 | F7: 20 | G7: 20 | J7: 1 | K7: Emergency Exist doors are not closed | L7: R | M7: A | N7: C | O7: I | Q7: R | R7: Responsible
B8: 2 | C8: Emergency exits pathways are not obstructed | D8: Stores | E8: 10 | F8: 10 | G8: 10 | J8: 2 | K8: Emergency exits pathways are not obstructed | L8: R | M8: A | N8: C | O8: I | Q8: A | R8: Accountable
B9: 3 | C9: Smoke detectors/beam detectors/Fire call points & Fire fighting equipment are not obstructed | D9: Stores | E9: 10 | F9: 10 | G9: 10 | J9: 3 | K9: Smoke detectors/beam detectors/Fire call points & Fire fighting equipment are not obstructed | L9: R | M9: A | N9: C | O9: I | Q9: C | R9: Consulted
B10: 4 | C10: Fire attendance registers are marked daily in all Departments | D10: Stores | E10: 10 | F10: 10 | G10: 10 | J10: 4 | K10: Fire attendance registers are marked daily in all Departments | L10: R | M10: A | N10: C | O10: I | Q10: I | R10: Informed
B11: First Aid | J11: First Aid
B12: 5 | C12: First aid box is not obstructed | D12: Stores | E12: 10 | F12: 10 | G12: 10 | J12: 5 | K12: First aid box is not obstructed | L12: R | M12: A | N12: C | O12: I
B13: Electrical Safety | J13: Electrical Safety
B14: 6 | C14: Electrical equipment (i.e. electrical panels, fuse/breaker boxes) are accessible and free of obstructions | D14: Stores | E14: 10 | F14: 10 | G14: 10 | J14: 6 | K14: Electrical equipment (i.e. electrical panels, fuse/breaker boxes) are accessible and free of obstructions | L14: R | M14: A | N14: C | O14: I
B15: Machine Safety | J15: Machine Safety
B16: 7 | C16: Material hoist handling safely. | D16: Stores | E16: 10 | F16: 0 | G16: 0 | H16: Material hoist door need to repair | J16: 7 | K16: Material hoist handling safely. | L16: R | M16: A | N16: C | O16: I
B17: Personal Protective Equipment (PPEs) | J17: Personal Protective Equipment (PPEs)
B18: 8 | C18: PPEs are used by all employees when they are necessary | D18: Stores | E18: 15 | F18: 0 | G18: 0 | H18: Not Providing for some of employees, safety shoes | J18: 8 | K18: PPEs are used by all employees when they are necessary | L18: R | M18: A | N18: C | O18: I
B19: Sharp Tool Safety | J19: Sharp Tool Safety
B20: 9 | C20: Sharp tools are hung & tied properly | D20: Stores | E20: 5 | F20: 5 | G20: 5 | J20: 14 | K20: Sharp tools are hung & tied properly | L20: R | M20: A | N20: C | O20: I
B21: 10 | C21: Tool inventory is maintained properly | D21: Stores | E21: 5 | F21: 5 | G21: 5 | J21: 15 | K21: Tool inventory is maintained properly | L21: R | M21: A | N21: C | O21: I
B22: 11 | C22: Not Handling loose blades | D22: Stores | E22: 5 | F22: 5 | G22: 5 | J22: 16 | K22: Not Handling loose blades | L22: R | M22: A | N22: C | O22: I
B23: Other | J23: Other
B24: 12 | C24: Stairs are clear of obstructions and not stored items under exit stairs | D24: Stores | E24: 15 | F24: 15 | G24: 15 | J24: 17 | K24: Stairs are clear of obstructions and not stored items under exit stairs | L24: R | M24: A | N24: C | O24: I
B25: 13 | C25: Cartons are stacked at safe height (6ft) (Material falling from a height) | D25: Stores | E25: 20 | F25: 20 | G25: 20 | J25: 18 | K25: Cartons are stacked at safe height (6ft) (Material falling from a height) | L25: R | M25: A | N25: C | O25: I
B26: 14 | C26: Loading and unloading area is closed with chain when there is no loading/unloading | D26: Stores | E26: 5 | F26: 5 | G26: 5 | J26: 20 | K26: Loading and unloading area is closed with chain when there is no loading/unloading | L26: R | M26: A | N26: C | O26: I
B27: 15 | C27: Proper housekeeping are maintained | D27: Stores | E27: 5 | F27: 5 | G27: 5 | J27: 21 | K27: Proper housekeeping are maintained | L27: R | M27: A | N27: C | O27: I
C28: Total | E28: =SUM(E7:E27) -> 155 | F28: =SUM(F5:F27) -> 130 | G28: =SUM(G5:G27) -> 130
C29: % | E29: =(E28/E28)*100 -> 100 | F29: =+F28/E28*100 -> 83.870968 | G29: =+G28/E28*100 -> 83.870968

Sheet Accessories
B4: Accessories (Binding/Winding/Piping/Macpi/Tape/Diecut/Veit/Strap/Laser) | J4: Accessories (Binding/Winding/Piping/Macpi/Tape/Diecut/Veit)
B5: Description | D5: Responsibility | E5: Allocated Score | F5: Accurate Score | G5: Adjustable score | H5: Remark | J5: Description
B6: Emergency response | J6: Emergency response | L6: Executive Accessories | M6: Manager Accessories | N6: Executive Compliance | O6: Assistant Compliance
B7: 1 | C7: Exist should be not closed | D7: Accessories | E7: 20 | F7: 20 | G7: 20 | J7: 1 | K7: Exist should be not closed | L7: R | M7: A | N7: C | O7: I | Q7: R | R7: Responsible
B8: 2 | C8: Emergency exits pathways are not obstructed | D8: Accessories | E8: 10 | F8: 10 | G8: 10 | J8: 2 | K8: Emergency exits pathways are not obstructed | L8: R | M8: A | N8: C | O8: I | Q8: A | R8: Accountable
B9: 3 | C9: Smoke detectors/beam detectors/Fire call points & Fire fighting equipment not obstructed | D9: Accessories | E9: 10 | F9: 10 | G9: 10 | J9: 3 | K9: Smoke detectors/beam detectors/Fire call points & Fire fighting equipment not obstructed | L9: R | M9: A | N9: C | O9: I | Q9: C | R9: Consulted
B10: 4 | C10: Fire attendance registers are marked daily in all Departments | D10: Accessories | E10: 10 | F10: 10 | G10: 10 | J10: 4 | K10: Fire attendance registers are marked daily in all Departments | L10: R | M10: A | N10: C | O10: I | Q10: I | R10: Informed
B11: First Aid | J11: First Aid
B12: 5 | C12: First aid box is not obstructed | D12: Accessories | E12: 10 | F12: 10 | G12: 10 | J12: 5 | K12: First aid box is not obstructed | L12: R | M12: A | N12: C | O12: I
B13: Electrical Safety | J13: Electrical Safety
B14: 6 | C14: Electrical equipment (i.e. electrical panels, fuse/breaker boxes) are accessible and free of obstructions | D14: Accessories | E14: 10 | F14: 0 | G14: 0 | H14: Exposed wirres are visible - veit | J14: 6 | K14: Electrical equipment (i.e. electrical panels, fuse/breaker boxes) are accessible and free of obstructions | L14: R | M14: A | N14: C | O14: I
B15: Machine Safety | J15: Machine Safety
B16: 7 | C16: Machine guards, dual hand operation and other safety process or features are not using while working with a machine | D16: Accessories | E16: 15 | F16: 0 | G16: 0 | H16: Emergency stop button not properly worked, Take time to stop the machine - Piping/Binding area machine | J16: 7 | K16: Machine guards, dual hand operation and other safety process or features are not using while working with a machine | L16: R | M16: A | N16: C | O16: I
B17: 8 | C17: Safety carpets are used for both iron workers and the machine workers | D17: Accessories | E17: 10 | F17: 0 | G17: 0 | J17: 8 | K17: Safety carpets are used for both iron workers and the machine workers | L17: R | M17: A | N17: C | O17: I
B18: Personal Protective Equipment (PPEs) | J18: Personal Protective Equipment (PPEs)
B19: 9 | C19: PPEs are used by all employees when they are necessary (hair nets/metal gloves/goggles etc) | D19: Accessories | E19: 15 | F19: 15 | G19: 15 | J19: 9 | K19: PPEs are used by all employees when they are necessary (hair nets/metal gloves/goggles etc) | L19: R | M19: A | N19: C | O19: I
B20: Chemical Safety | J20: Chemical Safety
B21: 10 | C21: Chemical containers are in good condition and stored in separate containers and incompatible chemicals stored separately | D21: Accessories | E21: 20 | F21: 20 | G21: 20 | J21: 10 | K21: Chemical containers are in good condition and stored in separate containers and incompatible chemicals stored separately | L21: R | M21: A | N21: C | O21: I
B22: 11 | C22: Chemical cans and secondary containers are named & labels are included name & GHS sign | D22: Accessories | E22: 15 | F22: 15 | G22: 15 | J22: 11 | K22: Chemical cans and secondary containers are named & labels are included name & GHS sign | L22: R | M22: A | N22: C | O22: I
B23: Sharp Tool Safety | J23: Sharp Tool Safety
B24: 12 | C24: Sharp tools are hung & tied properly (trimmers/ sessiors) | D24: Accessories | E24: 5 | F24: 5 | G24: 5 | J24: 12 | K24: Sharp tools are hung & tied properly (trimmers/ sessiors) | L24: R | M24: A | N24: C | O24: I
B25: 13 | C25: Safety rulers are used when using OLFA cutters | D25: Accessories | E25: 5 | F25: 5 | G25: 5 | J25: 13 | K25: Safety rulers are used when using OLFA cutters | L25: R | M25: A | N25: C | O25: I
B26: 14 | C26: Tool inventory is maintained properly | D26: Accessories | E26: 5 | F26: 0 | G26: 5 | H26: Tape section | J26: 14 | K26: Tool inventory is maintained properly | L26: R | M26: A | N26: C | O26: I
B27: 15 | C27: Not Handling loose blades (excepting tape section) | D27: Accessories | E27: 5 | F27: 5 | G27: 5 | J27: 15 | K27: Not Handling loose blades (excepting tape section) | L27: R | M27: A | N27: C | O27: I
B28: Other | J28: Other
B29: 16 | C29: Stairs are clear of obstructions and not stored items under exit stairs | D29: Accessories | E29: 15 | F29: 15 | G29: 15 | J29: 16 | K29: Stairs are clear of obstructions and not stored items under exit stairs | L29: R | M29: A | N29: C | O29: I
B30: 17 | C30: Not using broken irons & proper iron table clothes are used | D30: Accessories | E30: 10 | F30: 10 | G30: 10 | J30: 18 | K30: Not using broken irons & proper iron table clothes are used | L30: R | M30: A | N30: C | O30: I
B31: 18 | C31: Proper housekeeping are maintained | D31: Accessories | E31: 5 | F31: 5 | G31: 5 | J31: 19 | K31: Proper housekeeping are maintained | L31: R | M31: A | N31: C | O31: I
B32: 19 | C32: Food is not permitted in the production area | D32: Accessories | E32: 5 | F32: 5 | G32: 5
B33: 20 | C33: Facilities Maintenance | D33: Accessories | E33: 10 | F33: 0 | G33: 0 | H33: Cracked floor with holes was found in tape Section
B34: 21 | C34: Found unotherized cloth item | D34: Accessories | E34: 10 | F34: 0 | G34: 10 | H34: Laser
B35: 21 | C35: Calibrated measuring tape | D35: Accessories | E35: 5 | F35: 0 | G35: 5 | H35: Veit
C36: Total | E36: =SUM(E7:E35) -> 225 | F36: =SUM(F5:F35) -> 160 | G36: =SUM(G5:G35) -> 180
C37: % | E37: =(E36/E36)*100 -> 100 | F37: =+F36/E36*100 -> 71.111111 | G37: =+G36/E36*100 -> 80

Sheet Cutting
B4: Cutting | J4: Cutting
B5: Description | D5: Responsibility | E5: Allocated Score | F5: Accurate Score | G5: Adjustable score | H5: Remark | J5: Description
B6: Emergency response | J6: Emergency response | L6: Supervisor Cutting | M6: Senior Executive cutting | N6: Executive Compliance | O6: Assistant Compliance
B7: 1 | C7: Exist should be not closed | D7: Cutting | E7: 20 | F7: 20 | G7: 20 | J7: 1 | K7: Exist should be not closed | L7: R | M7: A | N7: C | O7: I | Q7: R | R7: Responsible
B8: 2 | C8: Emergency exits pathways are not obstructed | D8: Cutting | E8: 10 | F8: 10 | G8: 10 | J8: 2 | K8: Emergency exits pathways are not obstructed | L8: R | M8: A | N8: C | O8: I | Q8: A | R8: Accountable
B9: 3 | C9: Smoke detectors/beam detectors/Fire call points & Fire fighting equipment not obstructed | D9: Cutting | E9: 10 | F9: 10 | G9: 10 | J9: 3 | K9: Fire alarm system is unobstructed throughout the area | L9: R | M9: A | N9: C | O9: I | Q9: C | R9: Consulted
B10: 4 | C10: Fire attendance registers are marked daily in all Departments | D10: Cutting | E10: 10 | F10: 10 | G10: 10 | J10: 4 | K10: Smoke detectors/beam detectors/Fire call points & Fire fighting equipment not obstructed | L10: R | M10: A | N10: C | O10: I | Q10: I | R10: Informed
B11: First Aid | J11: 7 | K11: Fire attendance registers are marked daily in all Departments | L11: R | M11: A | N11: C | O11: I
B12: 5 | C12: First aid box is not obstructed | D12: Cutting | E12: 10 | F12: 10 | G12: 10 | J12: First Aid
B13: Electrical Safety | J13: 8 | K13: First aid box is not obstructed | L13: R | M13: A | N13: C | O13: I
B14: 6 | C14: Electrical equipment (i.e. electrical panels, fuse/breaker boxes) are accessible and free of obstructions | D14: Cutting | E14: 10 | F14: 10 | G14: 10 | J14: Electrical Safety
B15: Machine Safety | J15: 9 | K15: Electrical equipment (i.e. electrical panels, fuse/breaker boxes) are accessible and free of obstructions | L15: R | M15: A | N15: C | O15: I
B16: 7 | C16: Work point of the Band knife operator isolated through a safe railing/ Blades are coverd when not working | D16: Cutting | E16: 15 | F16: 15 | G16: 15 | J16: Machine Safety
B17: 8 | C17: Machine guards & dual hand operation are not using while working with a machine | D17: Cutting | E17: 15 | F17: 15 | G17: 15 | J17: 10 | K17: Work point of the Band knife operator isolated through a safe railing/ Blades are coverd when not working | L17: R | M17: A | N17: C | O17: I
B18: 9 | C18: Safety carpets are provided for both iron workers and the machine workers | D18: Cutting | E18: 10 | F18: 10 | G18: 10 | J18: 11 | K18: Machine guards & dual hand operation are not using while working with a machine | L18: R | M18: A | N18: C | O18: I
B19: Personal Protective Equipment (PPEs) | J19: 12 | K19: Safety carpets are provided for both iron workers and the machine workers | L19: R | M19: A | N19: C | O19: I
B20: 10 | C20: PPEs are used by all employees when they are necessary (hair nets/metal gloves/goggles etc) | D20: Cutting | E20: 15 | F20: 15 | G20: 15 | J20: Personal Protective Equipment (PPEs)
B21: Sharp Tool Safety | J21: 13 | K21: PPEs are used by all employees when they are necessary (hair nets/metal gloves/goggles etc) | L21: R | M21: A | N21: C | O21: I
B22: 11 | C22: Sharp tools are hung & tied properly (trimmers/ sessiors) | D22: Cutting | E22: 5 | F22: 5 | G22: 5 | J22: 14 | K22: PPE is stored in a clean cabinet or free of any contamination (Eg: dust) | L22: R | M22: A | N22: C | O22: I
B23: 12 | C23: Tool inventory is maintained properly | D23: Cutting | E23: 5 | F23: 5 | G23: 5 | J23: Chemical Safety
B24: 13 | C24: Numbering the scissors | D24: Cutting | E24: 5 | F24: 5 | G24: 5 | J24: 15 | K24: Chemical containers are in good condition and stored in separate containers and incompatible chemicals stored separately | L24: R | M24: A | N24: C | O24: I
B25: 14 | C25: Not Handling loose blades or Pins | D25: Cutting | E25: 5 | F25: 5 | G25: 5 | J25: 16 | K25: Chemical cans and secondary containers are named & labels are included name & GHS sign | L25: R | M25: A | N25: C | O25: I
B26: Other | J26: Sharp Tool Safety
B27: 15 | C27: Proper housekeeping are maintained | D27: Cutting | E27: 5 | F27: 5 | G27: 5 | J27: 17 | K27: Safety rulers are used when using OLFA cutters | L27: R | M27: A | N27: C | O27: I
B28: 16 | C28: Food items ara not permit in manufacturing area | D28: Cutting | E28: 5 | F28: 5 | G28: 5
C29: Total | E29: =SUM(E7:E28) -> 155 | F29: =SUM(F5:F28) -> 155 | G29: =SUM(G5:G28) -> 155 | J29: 18 | K29: Tool inventory is maintained properly | L29: R | M29: A | N29: C | O29: I
C30: % | E30: =(E29/E29)*100 -> 100 | F30: =+F29/E29*100 -> 100 | G30: =+G29/E29*100 -> 100 | J30: Other
J31: 19 | K31: Stairs are clear of obstructions and not stored items under exit stairs | L31: R | M31: A | N31: C | O31: I
J32: 20 | K32: Cartons are stacked at safe height (6ft) | L32: R | M32: A | N32: C | O32: I
J33: 21 | K33: Not using broken irons & proper iron table clothes are used | L33: R | M33: A | N33: C | O33: I
J34: 22 | K34: Proper housekeeping are maintained | L34: R | M34: A | N34: C | O34: I
K35: Total
K36: %

Sheet Ground floor modules & Molding
B4: Ground floor Production Modules & Molding | J4: Prodcution_Modules
B5: Description | D5: Responsibility | E5: Allocated Score | F5: Accurate Score | G5: Adjustable score | H5: Remark | J5: Description
B6: Emergency Response | J6: Emergency Response | L6: Executive Production | M6: Manager Production | N6: Executive Compliance | O6: Assistant Compliance
B7: 1 | C7: Exist should be not closed | D7: Production | E7: 20 | F7: 20 | G7: 20 | J7: 1 | K7: Exist should be not closed | L7: R | M7: A | N7: C | O7: I | Q7: R | R7: Responsible
B8: 2 | C8: Emergency exits pathways are not obstructed | D8: Production | E8: 10 | F8: 10 | G8: 10 | J8: 2 | K8: Emergency exits pathways are not obstructed | L8: R | M8: A | N8: C | O8: I | Q8: A | R8: Accountable
B9: 3 | C9: Smoke detectors/beam detectors/Fire call points & Fire fighting equipment not obstructed | D9: Production | E9: 10 | F9: 0 | G9: 0 | H9: By machine layout | J9: 3 | K9: Smoke detectors/beam detectors/Fire call points & Fire fighting equipment not obstructed | L9: R | M9: A | N9: C | O9: I | Q9: C | R9: Consulted
B10: 4 | C10: Fire attendance registers are marked daily in all Departments | D10: Production | E10: 10 | F10: 10 | G10: 10 | J10: 4 | K10: Fire attendance registers are marked daily in all Departments | L10: R | M10: A | N10: C | O10: I | Q10: I | R10: Informed
B11: First Aid | J11: First Aid
B12: 5 | C12: First aid box is not obstructed | D12: Production | E12: 10 | F12: 10 | G12: 10 | H12: By machine layout | J12: 5 | K12: First aid box is not obstructed | L12: R | M12: A | N12: C | O12: I
B13: Electrical Safety | J13: Electrical Safety
B14: 6 | C14: Electrical equipment (i.e. electrical panels, fuse/breaker boxes) are accessible and free of obstructions | D14: Production | E14: 10 | F14: 10 | G14: 10 | J14: 6 | K14: Electrical equipment (i.e. electrical panels, fuse/breaker boxes) are accessible and free of obstructions | L14: R | M14: A | N14: C | O14: I
B15: Machine Safety | J15: Machine Safety
B16: 7 | C16: Machine guards, dual hand operation and other safety features are not using while working with a machine | D16: Production | E16: 15 | F16: 15 | G16: 15 | J16: 7 | K16: Machine guards, dual hand operation and other safety features are not using while working with a machine | L16: R | M16: A | N16: C | O16: I
B17: 8 | C17: Safety carpets are used for both iron workers and the machine workers | D17: Production | E17: 10 | F17: 0 | G17: 0 | H17: Carpet not provide for all applicable employees/Missused | J17: 8 | K17: Safety carpets are used for both iron workers and the machine workers | L17: R | M17: A | N17: C | O17: I
B18: Personal Protective Equipment (PPEs) | J18: Personal Protective Equipment (PPEs)
B19: 9 | C19: PPEs are used by all employees when they are necessary | D19: Production | E19: 15 | F19: 15 | G19: 15 | J19: 9 | K19: PPEs are used by all employees when they are necessary | L19: R | M19: A | N19: C | O19: I
B20: Chemical Safety | J20: Chemical Safety
B21: 10 | C21: Chemical containers are in good condition and stored in separate containers and incompatible chemicals stored separately | D21: Production | E21: 20 | F21: 20 | G21: 20 | J21: 10 | K21: Chemical containers are in good condition and stored in separate containers and incompatible chemicals stored separately | L21: R | M21: A | N21: C | O21: I
B22: 11 | C22: Chemical cans and secondary containers are named & labels are included name & GHS sign | D22: Production | E22: 15 | F22: 15 | G22: 15 | J22: 11 | K22: Chemical cans and secondary containers are named & labels are included name & GHS sign | L22: R | M22: A | N22: C | O22: I
B23: 12 | C23: Spill kits available near chemical using areas | D23: Production | E23: 15 | F23: 15 | G23: 15 | J23: 12 | K23: Spill kits available near chemical using areas | L23: R | M23: A | N23: C | O23: I
B24: Sharp Tool Safety | J24: Sharp Tool Safety
B25: 13 | C25: Sharp tools are hung & tied properly (trimmers/ sessiors) | D25: Production | E25: 5 | F25: 5 | G25: 5 | J25: 13 | K25: Sharp tools are hung & tied properly (trimmers/ sessiors) | L25: R | M25: A | N25: C | O25: I
B26: 14 | C26: Safety rulers are used when using OLFA cutters | D26: Production | E26: 5 | F26: 5 | G26: 5 | J26: 14 | K26: Safety rulers are used when using OLFA cutters | L26: R | M26: A | N26: C | O26: I
B27: 15 | C27: Tool inventory is maintained properly | D27: Production | E27: 5 | F27: 5 | G27: 5 | J27: 15 | K27: Tool inventory is maintained properly | L27: R | M27: A | N27: C | O27: I
B28: 16 | C28: All tools are properly numbered | D28: Production | E28: 5 | F28: 5 | G28: 5
B29: 17 | C29: Not Handling loose blades (excepting tape section) | D29: Production | E29: 5 | F29: 5 | G29: 5 | J29: 16 | K29: Not Handling loose blades (excepting tape section) | L29: R | M29: A | N29: C | O29: I
B30: Other | J30: Other
B31: 18 | C31: Stairs are clear of obstructions and not stored items under exit stairs | D31: Production | E31: 15 | F31: 15 | G31: 15 | J31: 17 | K31: Stairs are clear of obstructions and not stored items under exit stairs | L31: R | M31: A | N31: C | O31: I
B32: 19 | C32: Cartons are stacked at safe height (6ft) | D32: Production | E32: 5 | F32: 5 | G32: 5 | J32: 18 | K32: Cartons are stacked at safe height (6ft) | L32: R | M32: A | N32: C | O32: I
B33: 20 | C33: Not using broken irons & proper iron table clothes are used | D33: Production | E33: 10 | F33: 10 | G33: 10 | J33: 19 | K33: Not using broken irons & proper iron table clothes are used | L33: R | M33: A | N33: C | O33: I
B34: 21 | C34: Exposed or hazardous electrical wires shall not be present | D34: Production | E34: 20 | F34: 0 | G34: 0 | H34: Exposed electrical wiring is visible
B35: 22 | C35: Proper housekeeping are maintained | D35: Production | E35: 5 | F35: 5 | G35: 5 | J35: 20 | K35: Proper housekeeping are maintained | L35: R | M35: A | N35: C | O35: I
B36: 23 | C36: Found unotherized chemical product | D36: Production | E36: 20 | F36: 0 | G36: 20
B37: 24 | C37: Food items ara not permit in manufacturing area | D37: Production | E37: 5 | F37: 5 | G37: 5
C38: Total | E38: =SUM(E7:E37) -> 265 | F38: =SUM(F7:F37) -> 205 | G38: =SUM(G7:G37) -> 225
C39: % | E39: =(E38/E38)*100 -> 100 | F39: =+F38/E38*100 -> 77.358491 | G39: =+G38/E38*100 -> 84.90566

Sheet Packing 
B4: Packing/ Data Entry Area near the Cutting | J4: Prodcution_Modules
B5: Description | D5: Responsibility | E5: Allocated Score | F5: Accurate Score | G5: Adjustable score | H5: Remark | J5: Description
B6: Emergency Response | J6: Emergency Response | L6: Executive Production | M6: Manager Production | N6: Executive Compliance | O6: Assistant Compliance
B7: 1 | C7: Exist should be not closed | D7: Production | E7: 20 | F7: 20 | G7: 20 | J7: 1 | K7: Exist should be not closed | L7: R | M7: A | N7: C | O7: I | Q7: R | R7: Responsible
B8: 2 | C8: Emergency exits pathways are not obstructed | D8: Production | E8: 10 | F8: 10 | G8: 10 | H8: Space issue raised | J8: 2 | K8: Emergency exits pathways are not obstructed | L8: R | M8: A | N8: C | O8: I | Q8: A | R8: Accountable
B9: 3 | C9: Smoke detectors/beam detectors/Fire call points & Fire fighting equipment not obstructed | D9: Production | E9: 10 | F9: 10 | G9: 10 | J9: 3 | K9: Smoke detectors/beam detectors/Fire call points & Fire fighting equipment not obstructed | L9: R | M9: A | N9: C | O9: I | Q9: C | R9: Consulted
B10: 4 | C10: Fire attendance registers are marked daily in all Departments | D10: Production | E10: 10 | F10: 10 | G10: 10 | J10: 4 | K10: Fire attendance registers are marked daily in all Departments | L10: R | M10: A | N10: C | O10: I | Q10: I | R10: Informed
B11: First Aid | J11: First Aid
B12: 5 | C12: First aid box is not obstructed | D12: Production | E12: 10 | F12: 10 | G12: 10 | J12: 5 | K12: First aid box is not obstructed | L12: R | M12: A | N12: C | O12: I
B13: 6 | C13: Electrical equipment (i.e. electrical panels, fuse/breaker boxes) are accessible and free of obstructions | D13: Production | E13: 10 | F13: 10 | G13: 10 | J13: 6 | K13: Electrical equipment (i.e. electrical panels, fuse/breaker boxes) are accessible and free of obstructions | L13: R | M13: A | N13: C | O13: I
B14: 7 | C14: Not obstructing the wheelchair | D14: Production | E14: 10 | F14: 10 | G14: 10 | J14: 7 | K14: Not obstructing the wheelchair | L14: R | M14: A | N14: C | O14: I
B15: Personal Protective Equipment (PPEs) | J15: Personal Protective Equipment (PPEs)
B16: 8 | C16: PPEs are used by all employees when they are necessary | D16: Production | E16: 15 | F16: 15 | G16: 15 | J16: 8 | K16: PPEs are used by all employees when they are necessary | L16: R | M16: A | N16: C | O16: I
B17: Sharp Tool Safety | J17: Sharp Tool Safety
B18: 9 | C18: Sharp tools are hung & tied properly (trimmers/ sessiors) | D18: Production | E18: 5 | F18: 5 | G18: 5 | J18: 9 | K18: Sharp tools are hung & tied properly (trimmers/ sessiors) | L18: R | M18: A | N18: C | O18: I
B19: 10 | C19: Safety rulers are used when using OLFA cutters | D19: Production | E19: 5 | F19: 5 | G19: 5 | J19: 10 | K19: Safety rulers are used when using OLFA cutters | L19: R | M19: A | N19: C | O19: I
B20: 11 | C20: Tool inventory is maintained properly | D20: Production | E20: 5 | F20: 5 | G20: 5 | J20: 11 | K20: Tool inventory is maintained properly | L20: R | M20: A | N20: C | O20: I
B21: 12 | C21: Not Handling loose blades & paper cutters | D21: Production | E21: 5 | F21: 5 | G21: 5 | J21: 12 | K21: Not Handling loose blades & paper cutters | L21: R | M21: A | N21: C | O21: I
B22: Other | J22: Other
B23: 13 | C23: Cartons are stacked at safe height (6ft) | D23: Production | E23: 5 | F23: 5 | G23: 5 | J23: 13 | K23: Cartons are stacked at safe height (6ft) | L23: R | M23: A | N23: C | O23: I
B24: 14 | C24: Proper housekeeping are maintained | D24: Production | E24: 5 | F24: 5 | G24: 5 | J24: 14 | K24: Proper housekeeping are maintained | L24: R | M24: A | N24: C | O24: I
B25: 15 | C25: Stairs are clear of obstructions and not stored items under exit stairs | D25: Production | E25: 15 | F25: 15 | G25: 15
C26: Total | E26: =SUM(E7:E25) -> 140 | F26: =SUM(F7:F25) -> 140 | G26: =SUM(G7:G25) -> 140
C27: % | E27: =(E26/E26)*100 -> 100 | F27: =+F26/E26*100 -> 100 | G27: =+G26/E26*100 -> 100

Sheet Audit room & Final Inspection
B4: Audit rooms & Final Inspection Area | J4: Lab
B5: Description | D5: Responsibility | E5: Allocated Score | F5: Accurate Score | G5: Adjustable score | H5: Remark | J5: Description
B6: Emergency Response | J6: Emergency Response | L6: Supervisor Lab | M6: Assistant Manger QA | N6: Executive Compliance | O6: Assistant Compliance
B7: 1 | C7: Exist should be not closed | D7: QA | E7: 20 | F7: 20 | G7: 20 | J7: 1 | K7: Exist should be not closed | L7: R | M7: A | N7: C | O7: I | Q7: R | R7: Responsible
B8: 2 | C8: Emergency exits pathways are not obstructed | D8: QA | E8: 10 | F8: 10 | G8: 10 | J8: 2 | K8: Emergency exits pathways are not obstructed | L8: R | M8: A | N8: C | O8: I | Q8: A | R8: Accountable
B9: 3 | C9: Smoke detectors/beam detectors/Fire call points & Fire fighting equipment not obstructed | D9: QA | E9: 10 | F9: 10 | G9: 10 | J9: 3 | K9: Smoke detectors/beam detectors/Fire call points & Fire fighting equipment not obstructed | L9: R | M9: A | N9: C | O9: I | Q9: C | R9: Consulted
B10: 4 | C10: Fire attendance registers are marked daily in all Departments | D10: QA | E10: 10 | F10: 10 | G10: 10 | J10: 4 | K10: Fire attendance registers are marked daily in all Departments | L10: R | M10: A | N10: C | O10: I | Q10: I | R10: Informed
B11: First Aid | J11: First Aid
B12: 5 | C12: First aid box is not obstructed | D12: QA | E12: 10 | F12: 10 | G12: 10 | J12: 5 | K12: First aid box is not obstructed | L12: R | M12: A | N12: C | O12: I
B13: Electrical Safety | J13: Electrical Safety
B14: 6 | C14: Electrical equipment (i.e. electrical panels, fuse/breaker boxes) are accessible and free of obstructions | D14: QA | E14: N/A | F14: N/A | G14: N/A | J14: 7 | K14: Electrical equipment (i.e. electrical panels, fuse/breaker boxes) are accessible and free of obstructions | L14: R | M14: A | N14: C | O14: I
B15: Personal Protective Equipment (PPEs) | J15: Personal Protective Equipment (PPEs)
B16: 7 | C16: PPEs are used by all employees when they are necessary | D16: QA | E16: N/A | F16: N/A | G16: N/A | J16: 8 | K16: PPEs are used by all employees when they are necessary | L16: R | M16: A | N16: C | O16: I
B17: Sharp Tool Safety | J17: Sharp Tool Safety
B18: 8 | C18: Sharp tools are hung & tied properly (trimmers/ sessiors) | D18: QA | E18: 5 | F18: 5 | G18: 5 | J18: 9 | K18: Sharp tools are hung & tied properly (trimmers/ sessiors) | L18: R | M18: A | N18: C | O18: I
B19: 9 | C19: Tool inventory is maintained properly | D19: QA | E19: 5 | F19: 0 | G19: 5 | H19: No maintain tool inventory Properly | J19: 10 | K19: Tool inventory is maintained properly | L19: R | M19: A | N19: C | O19: I
B20: 10 | C20: Not Handling loose blades | D20: QA | E20: 5 | F20: 5 | G20: 5 | J20: 11 | K20: Not Handling loose blades | L20: R | M20: A | N20: C | O20: I
B21: Other | J21: Other
B22: 11 | C22: Cartons are stacked at safe height (6ft) | D22: QA | E22: 5 | F22: 5 | G22: 5 | J22: 12 | K22: Cartons are stacked at safe height (6ft) | L22: R | M22: A | N22: C | O22: I
B23: 12 | C23: Found unotherized chemical product | D23: QA | E23: 10 | F23: 0 | G23: 10
B24: 11 | C24: Proper housekeeping are maintained | D24: QA | E24: 5 | F24: 5 | G24: 5 | J24: 13 | K24: Proper housekeeping are maintained | L24: R | M24: A | N24: C | O24: I
C25: Total | E25: =SUM(E7:E24) -> 95 | F25: =SUM(F5:F24) -> 80 | G25: =SUM(G5:G24) -> 95
C26: % | E26: =(E25/E25)*100 -> 100 | F26: =+F25/E25*100 -> 84.210526 | G26: =+G25/E25*100 -> 100
C28: Sounders for exits
C29: Wheelchair obstruction

Sheet Lab & CPI
B4: Lab/Trim Inspection | J4: Lab
